Building DAG of jobs...
Using shell: /bin/bash
Provided cores: 1
Rules claiming more threads will be scaled down.
Job counts:
	count	jobs
	1	all
	1	create_indel_table
	2

[Mon Aug 13 13:54:03 2018]
rule create_indel_table:
    input: tmp/roary/gene_presence_absence.Rtab, tmp/indel.list
    output: /net/metagenomics/data/from_moni/old.tzuhao/seq2geno/dev_versions/v4/results/annot.tab, indel_annot.txt, indels_stats.txt, roary_PA14_abricate.txt
    jobid: 1

    [Mon Aug 13 13:54:04 2018]
    Error in rule create_indel_table:
        jobid: 1
        output: /net/metagenomics/data/from_moni/old.tzuhao/seq2geno/dev_versions/v4/results/annot.tab, indel_annot.txt, indels_stats.txt, roary_PA14_abricate.txt

RuleException:
CalledProcessError in line 78 of /net/sgi/metagenomics/data/from_moni/old.tzuhao/seq2geno/dev_versions/v4/CREATE_INDEL_TABLE.smk:
Command ' set -euo pipefail;  
        source activate py27
        python indel_detection/generate_indel_features.py         <(cut -f1 tmp/roary/gene_presence_absence.Rtab| tail -n+2 )         /net/metagenomics/data/from_moni/old.tzuhao/seq2geno/dev_versions/v4/results/annot.tab indel_annot.txt         indels_stats.txt roary_PA14_abricate.txt 
        source deactivate ' returned non-zero exit status 1.
  File "/net/sgi/metagenomics/data/from_moni/old.tzuhao/seq2geno/dev_versions/v4/CREATE_INDEL_TABLE.smk", line 78, in __rule_create_indel_table
  File "/home/thkuo/miniconda3/envs/phypal/lib/python3.6/concurrent/futures/thread.py", line 55, in run
Shutting down, this might take some time.
Exiting because a job execution failed. Look above for error message
Complete log: /net/sgi/metagenomics/data/from_moni/old.tzuhao/seq2geno/dev_versions/v4/.snakemake/log/2018-08-13T135358.510674.snakemake.log
