FileNotFoundError in line 5 of /net/sgi/metagenomics/data/from_moni/old.tzuhao/seq2geno/dev_versions/v7/test.smk:
File b'/net/metagenomics/data/from_moni/old.tzuhao/seq2geno/dev_versions/v7/data/test.samples' does not exist
  File "/net/sgi/metagenomics/data/from_moni/old.tzuhao/seq2geno/dev_versions/v7/test.smk", line 16, in <module>
  File "/net/sgi/metagenomics/data/from_moni/old.tzuhao/seq2geno/dev_versions/v7/test.smk", line 5, in parse_samples
  File "/home/thkuo/miniconda3/envs/seq2geno/lib/python3.6/site-packages/pandas/io/parsers.py", line 678, in parser_f
  File "/home/thkuo/miniconda3/envs/seq2geno/lib/python3.6/site-packages/pandas/io/parsers.py", line 440, in _read
  File "/home/thkuo/miniconda3/envs/seq2geno/lib/python3.6/site-packages/pandas/io/parsers.py", line 787, in __init__
  File "/home/thkuo/miniconda3/envs/seq2geno/lib/python3.6/site-packages/pandas/io/parsers.py", line 1014, in _make_engine
  File "/home/thkuo/miniconda3/envs/seq2geno/lib/python3.6/site-packages/pandas/io/parsers.py", line 1708, in __init__
  File "pandas/_libs/parsers.pyx", line 384, in pandas._libs.parsers.TextReader.__cinit__
  File "pandas/_libs/parsers.pyx", line 695, in pandas._libs.parsers.TextReader._setup_parser_source
