KeyError in line 8 of /net/sgi/metagenomics/data/from_moni/old.tzuhao/seq2geno/dev_versions/v7/test.smk:
'dna_reads'
  File "/net/sgi/metagenomics/data/from_moni/old.tzuhao/seq2geno/dev_versions/v7/test.smk", line 13, in <module>
  File "/net/sgi/metagenomics/data/from_moni/old.tzuhao/seq2geno/dev_versions/v7/test.smk", line 8, in parse_samples
  File "/home/thkuo/miniconda3/envs/seq2geno/lib/python3.6/site-packages/pandas/core/frame.py", line 2688, in __getitem__
  File "/home/thkuo/miniconda3/envs/seq2geno/lib/python3.6/site-packages/pandas/core/frame.py", line 2695, in _getitem_column
  File "/home/thkuo/miniconda3/envs/seq2geno/lib/python3.6/site-packages/pandas/core/generic.py", line 2489, in _get_item_cache
  File "/home/thkuo/miniconda3/envs/seq2geno/lib/python3.6/site-packages/pandas/core/internals.py", line 4115, in get
  File "/home/thkuo/miniconda3/envs/seq2geno/lib/python3.6/site-packages/pandas/core/indexes/base.py", line 3080, in get_loc
  File "pandas/_libs/index.pyx", line 140, in pandas._libs.index.IndexEngine.get_loc
  File "pandas/_libs/index.pyx", line 162, in pandas._libs.index.IndexEngine.get_loc
  File "pandas/_libs/hashtable_class_helper.pxi", line 1492, in pandas._libs.hashtable.PyObjectHashTable.get_item
  File "pandas/_libs/hashtable_class_helper.pxi", line 1500, in pandas._libs.hashtable.PyObjectHashTable.get_item
